mplus_output/uni-14-HRS_W14.out
Mplus VERSION 8.1 (Mac)
MUTHEN & MUTHEN
05/27/2020  10:28 PM

INPUT INSTRUCTIONS

  DATA:
  FILE = "uni-14-HRS_W14.dat";

  VARIABLE:
  NAMES = mplusid UDAT UDAY UMON UYER UIWR UDWR USUB UBAK UNM1 UNM2 UNM5 UNM6 URE3
       URE5 URE6 UANI UVA1;
   MISSING=.;
   CATEGORICAL ARE all; idvariable = mplusid;
  ANALYSIS:
  estimator = wlsmv; coverage=0;
  MODEL:
  g by UDAT * ;
   g by UDAY * ;
   g by UMON * ;
   g by UYER * ;
   g by UIWR * ;
   g by UDWR * ;
   g by USUB * ;
   g by UBAK * ;
   g by UNM1 * ;
   g by UNM2 * ;
   g by UNM5 * ;
   g by UNM6 * ;
   g by URE3 * ;
   g by URE5 * ;
   g by URE6 * ;
   g by UANI * ;
   g by UVA1 * ;
   g @ 1;

  OUTPUT:
  standardized; svalues;



*** WARNING
  Data set contains cases with missing on all variables.
  These cases were not included in the analysis.
  Number of cases with missing on all variables:  1054
   1 WARNING(S) FOUND IN THE INPUT INSTRUCTIONS




SUMMARY OF ANALYSIS

Number of groups                                                 1
Number of observations                                       17693

Number of dependent variables                                   17
Number of independent variables                                  0
Number of continuous latent variables                            1

Observed dependent variables

  Binary and ordered categorical (ordinal)
   UDAT        UDAY        UMON        UYER        UIWR        UDWR
   USUB        UBAK        UNM1        UNM2        UNM5        UNM6
   URE3        URE5        URE6        UANI        UVA1

Continuous latent variables
   G

Variables with special functions

  ID variable           MPLUSID

Estimator                                                    WLSMV
Maximum number of iterations                                  1000
Convergence criterion                                    0.500D-04
Maximum number of steepest descent iterations                   20
Maximum number of iterations for H1                           2000
Convergence criterion for H1                             0.100D-03
Parameterization                                             DELTA
Link                                                        PROBIT

Input data file(s)
  uni-14-HRS_W14.dat

Input data format  FREE


SUMMARY OF DATA

     Number of missing data patterns           588


COVARIANCE COVERAGE OF DATA

Minimum covariance coverage value   0.000


     PROPORTION OF DATA PRESENT


           Covariance Coverage
              UDAT          UDAY          UMON          UYER          UIWR
              ________      ________      ________      ________      ________
 UDAT           0.531
 UDAY           0.529         0.541
 UMON           0.529         0.537         0.539
 UYER           0.527         0.535         0.534         0.537
 UIWR           0.527         0.538         0.536         0.534         0.994
 UDWR           0.527         0.537         0.535         0.534         0.994
 USUB           0.500         0.508         0.507         0.506         0.944
 UBAK           0.527         0.537         0.535         0.534         0.989
 UNM1           0.528         0.538         0.536         0.535         0.541
 UNM2           0.503         0.512         0.511         0.510         0.513
 UNM5           0.519         0.528         0.526         0.526         0.528
 UNM6           0.381         0.384         0.384         0.384         0.383
 URE3           0.478         0.486         0.485         0.484         0.906
 URE5           0.420         0.426         0.425         0.425         0.812
 URE6           0.347         0.351         0.351         0.351         0.675
 UANI           0.525         0.535         0.534         0.532         0.538
 UVA1           0.370         0.377         0.376         0.374         0.677


           Covariance Coverage
              UDWR          USUB          UBAK          UNM1          UNM2
              ________      ________      ________      ________      ________
 UDWR           0.994
 USUB           0.943         0.947
 UBAK           0.988         0.944         0.993
 UNM1           0.541         0.510         0.540         0.544
 UNM2           0.513         0.489         0.513         0.515         0.516
 UNM5           0.528         0.501         0.528         0.529         0.505
 UNM6           0.383         0.370         0.383         0.384         0.376
 URE3           0.906         0.881         0.906         0.489         0.469
 URE5           0.812         0.799         0.811         0.427         0.413
 URE6           0.674         0.672         0.675         0.351         0.344
 UANI           0.538         0.507         0.538         0.539         0.512
 UVA1           0.677         0.642         0.676         0.379         0.359


           Covariance Coverage
              UNM5          UNM6          URE3          URE5          URE6
              ________      ________      ________      ________      ________
 UNM5           0.532
 UNM6           0.384         0.386
 URE3           0.481         0.359         0.910
 URE5           0.422         0.324         0.776         0.814
 URE6           0.348         0.279         0.671         0.624         0.677
 UANI           0.527         0.382         0.486         0.425         0.350
 UVA1           0.370         0.264         0.615         0.546         0.447


           Covariance Coverage
              UANI          UVA1
              ________      ________
 UANI           0.542
 UVA1           0.377         0.681


UNIVARIATE PROPORTIONS AND COUNTS FOR CATEGORICAL VARIABLES

    UDAT
      Category 1    0.193         1811.000
      Category 2    0.807         7577.000
    UDAY
      Category 1    0.040          386.000
      Category 2    0.960         9183.000
    UMON
      Category 1    0.036          344.000
      Category 2    0.964         9191.000
    UYER
      Category 1    0.038          357.000
      Category 2    0.962         9149.000
    UIWR
      Category 1    0.008          147.000
      Category 2    0.010          177.000
      Category 3    0.032          570.000
      Category 4    0.087         1534.000
      Category 5    0.164         2878.000
      Category 6    0.454         7987.000
      Category 7    0.147         2581.000
      Category 8    0.066         1161.000
      Category 9    0.024          426.000
      Category 10    0.007          131.000
    UDWR
      Category 1    0.064         1119.000
      Category 2    0.041          723.000
      Category 3    0.079         1395.000
      Category 4    0.141         2473.000
      Category 5    0.201         3540.000
      Category 6    0.344         6056.000
      Category 7    0.078         1366.000
      Category 8    0.035          620.000
      Category 9    0.012          214.000
      Category 10    0.004           75.000
    USUB
      Category 1    0.042          709.000
      Category 2    0.114         1915.000
      Category 3    0.090         1511.000
      Category 4    0.136         2272.000
      Category 5    0.205         3426.000
      Category 6    0.413         6919.000
    UBAK
      Category 1    0.072         1267.000
      Category 2    0.928        16302.000
    UNM1
      Category 1    0.011          110.000
      Category 2    0.989         9520.000
    UNM2
      Category 1    0.032          289.000
      Category 2    0.968         8849.000
    UNM5
      Category 1    0.011          100.000
      Category 2    0.989         9306.000
    UNM6
      Category 1    0.116          793.000
      Category 2    0.884         6032.000
    URE3
      Category 1    0.253         4067.000
      Category 2    0.747        12032.000
    URE5
      Category 1    0.535         7708.000
      Category 2    0.465         6698.000
    URE6
      Category 1    0.518         6205.000
      Category 2    0.365         4374.000
      Category 3    0.117         1396.000
    UANI
      Category 1    0.004           40.000
      Category 2    0.040          382.000
